Workbook
Name Commercial: User_Inputs!$L$20:$L$28
Name Factory: User_Inputs!$L$31:$L$38
Name Home: User_Inputs!$L$4:$L$10
Name Hospital: User_Inputs!$L$41:$L$45
Name Hotel: User_Inputs!$L$13:$L$17
Name School: User_Inputs!$L$48:$L$53

Sheet Overview
A1: Solarvy Energy Platform Calculation Engine - Master Workbook
A3: Purpose
A4: How to use | B4: Inputs in blue tab
A5: Input routes
A6: Objectives
A7: Primary output | B7: Outputs in green tab

Sheet User_Inputs
A1: User Inputs
A3: Assessment Identity | I3: State | J3: City | L3: Home_Templates | N3: Home_Templates | Q3: Category | R3: Templates
A4: Assessment_ID | B4: SV-0001 | I4: Abia | J4: Abuja | L4: Studio / Self-contained | N4: Studio / Self-contained - Essential | P4: 1 | Q4: Home | R4: Studio / Self-contained - Essential
A5: Scenario_Name | B5: Base Case | I5: Adamawa | J5: Lagos | L5: 1-Bedroom Flat | N5: Studio / Self-contained - Standard | P5: 2 | Q5: Home | R5: Studio / Self-contained - Standard
A6: Currency_Symbol | B6: ₦ | I6: Akwa Ibom | J6: Kano | L6: 2-Bedroom Flat | N6: 1-Bedroom Flat - Essential | P6: 3 | Q6: Home | R6: 1-Bedroom Flat - Essential
A7: Country | B7: Nigeria | I7: Anambra | J7: Ibadan | L7: 3-Bedroom House | N7: 1-Bedroom Flat - Standard | P7: 4 | Q7: Home | R7: 1-Bedroom Flat - Standard
A8: State | B8: Lagos | I8: Bauchi | J8: Port Harcourt | L8: 4-Bedroom Duplex | N8: 1-Bedroom Flat - Comfort | P8: 5 | Q8: Home | R8: 1-Bedroom Flat - Comfort
A9: City | I9: Bayelsa | J9: Benin City | L9: 5-Bedroom Duplex / Large Home | N9: 2-Bedroom Flat - Essential | P9: 6 | Q9: Home | R9: 2-Bedroom Flat - Essential
A10: Building Information | B10: Home | C10: Property_Type | I10: Benue | J10: Kaduna | L10: Mini Estate / Shared Services | N10: 2-Bedroom Flat - Standard | P10: 7 | Q10: Home | R10: 2-Bedroom Flat - Standard
A11: Template | B11: 2-Bedroom Flat | C11: =B11 -> 2-Bedroom Flat | D11: =IF(C11="Studio / Self-contained",1, IF(C11="1-Bedroom Flat",2, IF(C11="2-Bedroom Flat",3, IF(C11="3-Bedroom House",4, IF(C11="4-Bedroom Duplex",5, IF(C11="5-Bedroom Duplex / Large Home",6, IF(C11="Mini Estate / Shared Services",7,IF(C11="Short-let Apartment - Standard",8, IF(C11="Guest House - 6 Rooms",9, IF(C11="Small Hotel - 12 Rooms Partial Backup",10, IF(C11="Medium Hotel - 25 Rooms Critical Loads",11, IF(C11="Lounge / Bar",12,IF(C11="Small Shop / Retail Kiosk",13, IF(C11="Pharmacy",14, IF(C11="Supermarket / Grocery",15, IF(C11="Salon / Barbershop",16, IF(C11="Small Office",17, IF(C11="Restaurant / Cafe",18, IF(C11="Bakery",19, IF(C11="Fuel Station Retail / Office",20,IF(C11="Bank / ATM Lobby",21, IF(C11="Warehouse",22, IF(C11="Cold Room / Frozen Storage",23, IF(C11="Light Factory / Small Production",24, IF(C11="Welding Workshop",25, IF(C11="Poultry Farm",26, IF(C11="Irrigation Pumping",27, IF(C11="Agro-Processing / Milling",28,IF(C11="Printing / Small Manufacturing",29, IF(C11="Small Clinic",30, IF(C11="Diagnostic Lab",31, IF(C11="Maternity Clinic",32, IF(C11="Small Hospital - Critical Loads",33, IF(C11="Dental Clinic",34, IF(C11="Nursery / Primary School",35, IF(C11="Secondary School",36, IF(C11="Computer Lab / Training Centre",37, IF(C11="Training Centre / Office",38, IF(C11="Church / Mosque / Event Hall",39,IF(C11="Boarding School Common Services",40)))))))))))))))))))))))))))))))))))))))) -> 3 | I11: Borno | J11: Maiduguri | N11: 2-Bedroom Flat - Comfort | P11: 8 | Q11: Home | R11: 2-Bedroom Flat - Comfort
A12: Usage Profile | B12: Standard | I12: Cross River | J12: Zaria | L12: Hotel_Templates | N12: 3-Bedroom Flat - Standard | P12: 9 | Q12: Home | R12: 3-Bedroom Flat - Standard
A13: Current Power Setup | B13: Grid + Generator | C13: Power_Setup | I13: Delta | J13: Aba | L13: Short-let Apartment - Standard | N13: 3-Bedroom House - Standard | P13: 10 | Q13: Home | R13: 3-Bedroom House - Standard
A14: Main Objective | B14: Reduce Diesel Use | C14: Objective_Mode | I14: Ebonyi | J14: Onitsha | L14: Guest House - 6 Rooms | N14: 3-Bedroom House - Comfort | P14: 11 | Q14: Home | R14: 3-Bedroom House - Comfort
A15: Choose Input Method | B15: Appliances | C15: Input_Method | I15: Edo | J15: Owerri | L15: Small Hotel - 12 Rooms Partial Backup | N15: 4-Bedroom Duplex - Essential | P15: 12 | Q15: Home | R15: 4-Bedroom Duplex - Essential
I16: Ekiti | J16: Enugu | L16: Medium Hotel - 25 Rooms Critical Loads | N16: 4-Bedroom Duplex - Standard | P16: 13 | Q16: Home | R16: 4-Bedroom Duplex - Standard
A17: Site and Usage Inputs | I17: Enugu | J17: Abeokuta | L17: Lounge / Bar | N17: 4-Bedroom Duplex - Comfort | P17: 14 | Q17: Home | R17: 4-Bedroom Duplex - Comfort
A18: Monthly_Usage_kWh | B18: 0 | I18: Gombe | J18: Jos | N18: 5-Bedroom Duplex / Large Home - Standard | P18: 15 | Q18: Home | R18: 5-Bedroom Duplex / Large Home - Standard
A19: Peak_Load_kW | B19: 0 | I19: Imo | J19: Warri | L19: Commercial Building_Templates | N19: 5-Bedroom Duplex / Large Home - Premium | P19: 16 | Q19: Home | R19: 5-Bedroom Duplex / Large Home - Premium
A20: Outage Hours per Day | B20: 6 | C20: Outage_Hours_per_Day | I20: Jigawa | J20: Sokoto | L20: Small Shop / Retail Kiosk | N20: Mini Estate / Shared Services | P20: 17 | Q20: Home | R20: Mini Estate / Shared Services
A21: Roof Area | B21: 200 | C21: Roof_Area_m2 | I21: Kaduna | J21: Ilorin | L21: Pharmacy | P21: 18 | Q21: Hotel | R21: Short-let Apartment - Standard
A22: Roof_Usability_Factor | B22: 0.6 | I22: Kano | J22: Oyo | L22: Supermarket / Grocery | N22: Hotel_Templates | P22: 19 | Q22: Hotel | R22: Guest House - 6 Rooms
A23: Daytime_Load_Share | B23: 0.15 | I23: Katsina | J23: Uyo | L23: Salon / Barbershop | N23: Short-let Apartment - Standard | P23: 20 | Q23: Hotel | R23: Small Hotel - 12 Rooms Partial Backup
A24: Critical_Load_Percent | B24: 0.6 | I24: Kebbi | J24: Calabar | L24: Small Office | N24: Guest House - 6 Rooms | P24: 21 | Q24: Hotel | R24: Medium Hotel - 25 Rooms Critical Loads
A25: Backup Duration Required | B25: 4 | C25: Backup_Hours_Target | I25: Kogi | J25: Osogbo | L25: Restaurant / Cafe | N25: Small Hotel - 12 Rooms Partial Backup | P25: 22 | Q25: Hotel | R25: Lounge / Bar
A26: Target_Solar_Share | B26: 0.9 | I26: Kwara | J26: Akure | L26: Bakery | N26: Medium Hotel - 25 Rooms Critical Loads | P26: 23 | Q26: Commercial | R26: Small Shop / Retail Kiosk
A27: Battery_DoD | B27: 0.2 | I27: Lagos | J27: Katsina | L27: Fuel Station Retail / Office | N27: Lounge / Bar | P27: 24 | Q27: Commercial | R27: Pharmacy
I28: Nasarawa | J28: Minna | L28: Bank / ATM Lobby | P28: 25 | Q28: Commercial | R28: Supermarket / Grocery
A29: Commercial Inputs | I29: Niger | J29: Makurdi | N29: Commercial Building_Templates | P29: 26 | Q29: Commercial | R29: Salon / Barbershop
A30: Grid_Tariff_per_kWh | B30: 209.5 | E30: Band A = N209.50/kWh | I30: Ogun | J30: Bauchi | L30: Factory_Templates | N30: Small Shop / Retail Kiosk | P30: 27 | Q30: Commercial | R30: Small Office
A31: Diesel_Price_per_Litre | B31: 1200 | E31: Band B = N63.00/kWh | I31: Ondo | J31: Gombe | L31: Warehouse | N31: Pharmacy | P31: 28 | Q31: Commercial | R31: Restaurant / Cafe
A32: Generator_kWh_per_Litre | B32: 3.5 | E32: Band C = N50.00/kWh | I32: Osun | J32: Yola | L32: Cold Room / Frozen Storage | N32: Supermarket / Grocery | P32: 29 | Q32: Commercial | R32: Bakery
A33: PV_Capex_per_kWp | B33: =IF($B$10="Home", 300000,IF($B$10="Office",420000,IF($B$10="Factory",320000,550000))) -> 300000 | E33: Band D = N43.00/kWh | I33: Oyo | J33: Jalingo | L33: Light Factory / Small Production | N33: Salon / Barbershop | P33: 30 | Q33: Commercial | R33: Fuel Station Retail / Office
A34: Battery_Capex_per_kWh | B34: =IF($B$10="Home",260000,IF($B$10="Office",350000,IF($B$10="Factory",300000,420000))) -> 260000 | E34: Band E = N40.00/kWh | I34: Plateau | J34: Damaturu | L34: Welding Workshop | N34: Small Office | P34: 31 | Q34: Commercial | R34: Bank / ATM Lobby
A35: Inverter_Capex_per_kW | B35: =IF($B$10="Home",230000,IF($B$10="Office",300000,IF($B$10="Factory",220000,380000))) -> 230000 | I35: Rivers | J35: Dutse | L35: Poultry Farm | N35: Restaurant / Cafe | P35: 32 | Q35: Factory | R35: Warehouse
A36: BOS_Factor | B36: =IF($B$10="Home",0.12,IF($B$10="Office",0.15,IF($B$10="Factory",0.12,0.2))) -> 0.12 | I36: Sokoto | J36: Gusau | L36: Irrigation Pumping | N36: Bakery | P36: 33 | Q36: Factory | R36: Cold Room / Frozen Storage
A37: Annual_OM_Rate | B37: 0.02 | I37: Taraba | J37: Birnin Kebbi | L37: Agro-Processing / Milling | N37: Fuel Station Retail / Office | P37: 34 | Q37: Factory | R37: Light Factory / Small Production
A38: Discount_Rate | B38: 0.15 | I38: Yobe | J38: Lokoja | L38: Printing / Small Manufacturing | N38: Bank / ATM Lobby | P38: 35 | Q38: Factory | R38: Welding Workshop
A39: System_Life_Years | B39: 15 | I39: Zamfara | J39: Asaba | P39: 36 | Q39: Factory | R39: Poultry Farm
I40: FCT Abuja | J40: Awka | L40: Hospital_Templates | N40: Factory_Templates | P40: 37 | Q40: Factory | R40: Irrigation Pumping
A41: Regional Technical Inputs / Overrides | J41: Ado-Ekiti | L41: Small Clinic | N41: Warehouse | P41: 38 | Q41: Factory | R41: Agro-Processing / Milling
...

Sheet Bill_Input
A1: Bill Input
A3: User-entered bill route
A4: Field | B4: Value | C4: Unit / Notes | D4: Formula / Derivation
A5: Monthly Electricity Usage | B5: =User_Inputs!B18 -> 0 | C5: kWh/month | D5: Monthly_Usage_kWh_Direct
A6: Average Monthly Electricity Spend | B6: 556000 | C6: Currency/month | D6: This is an input | E6: Monthly_Spend
A7: Tariff_per_kWh | B7: =IF(B5>0, B6/B5, User_Inputs!B30) -> 209.5 | C7: Currency/kWh | D7: linked from User_Inputs if not overridden
A8: Billing_Days | B8: 30 | C8: days
A9: If only spend known -> Estimated_kWh | B9: =IF(B5>0,B5,IFERROR(B6/B7,0)) -> 2653.9379 | C9: kWh/month | D9: =IF(B5>0,B5,IFERROR(B6/B7,0)) -> 2653.9379
A10: Effective_Bill_Monthly_kWh | B10: =IF(B5>0,B5,IFERROR(B6/B7,0)) -> 2653.9379 | C10: kWh/month | D10: =IF(B5>0,B5,B9) -> 2653.9379
B11: =IF(B5>0,B5,B10) -> 2653.9379
A13: Estimated Monthly spend | B13: =Appliance_Input!L5*B7 -> 50625.675

Sheet Equipment Default
A1: Equipment | B1: Wattage | C1: Hours/Day | D1: Usage Pattern | E1: Duty Cycle | F1: Surge Factor | G1: Critical by Default? | H1: Notes
A2: LED bulb | B2: 10 | C2: 6 | D2: Continuous | E2: 1 | F2: 1 | G2: Yes | H2: Lighting usually continuous when switched on
A3: Fan | B3: 60 | C3: 8 | D3: Continuous | E3: 1 | F3: 1.2 | G3: Optional | H3: Ceiling/standing fan
A4: TV | B4: 100 | C4: 6 | D4: Continuous | E4: 1 | F4: 1.2 | G4: Optional | H4: Average LED TV
A5: Router | B5: 15 | C5: 24 | D5: Continuous | E5: 1 | F5: 1 | G5: Yes | H5: Internet is often critical for remote work
A6: Refrigerator | B6: 150 | C6: 24 | D6: Cycles on/off | E6: 0.4 | F6: 2 | G6: Yes | H6: Compressor duty cycle varies
A7: Deep freezer | B7: 250 | C7: 24 | D7: Cycles on/off | E7: 0.45 | F7: 2.5 | G7: Optional | H7: Higher compressor surge
A8: AC 1HP | B8: 900 | C8: 5 | D8: Cycles heavily | E8: 0.6 | F8: 3 | G8: Optional | H8: Use inverter/non-inverter distinction later
A9: AC 1.5HP | B9: 1200 | C9: 5 | D9: Cycles heavily | E9: 0.6 | F9: 3.5 | G9: Optional | H9: High impact on battery sizing
A10: Water pump | B10: 1100 | C10: 1 | D10: Short use | E10: 1 | F10: 3 | G10: Yes | H10: Large surge; use short hours
A11: Display fridge | B11: 300 | C11: 24 | D11: Cycles on/off | E11: 0.5 | F11: 2.5 | G11: Yes | H11: Commercial refrigeration
A12: Medical refrigerator | B12: 180 | C12: 24 | D12: Cycles on/off | E12: 0.45 | F12: 2 | G12: Yes | H12: Critical healthcare load
A13: Computer / POS | B13: 120 | C13: 8 | D13: Continuous | E13: 1 | F13: 1.2 | G13: Yes | H13: Commercial ICT
... A16: Compressor | B16: 3000 | C16: 4 | D16: Cycles heavily | E16: 0.6 | F16: 3 | G16: Depends | H16: High surge and duty variation

Sheet Category Menu
A1: Category | B1: Column1 | C1: Column2 | D1: Column3 | E1: Column4
A2: Home
A3: Hotel
A4: Commercial
A5: Factory
A6: Hospital
A7: School

Sheet Appliance_Library
A1: Appliance Library
A3: Solarvy Category | B3: Template Name | C3: Template Level | D3: Equipment | E3: Qty | F3: Wattage W | G3: Hours/Day | H3: Duty Cycle | I3: Critical Load? | J3: Surge Factor | K3: Daily Wh | L3: Daily kWh | M3: Running W | N3: Surge W | O3: Notes
A4: Home | B4: Studio / Self-contained - Standard | C4: Standard | D4: LED Bulbs | E4: 6 | F4: 10 | G4: 6 | H4: 1 | I4: Yes | J4: 1 | K4: =E4*F4*G4*H4 -> 360 | L4: =K4/1000 -> 0.36 | M4: =E4*F4 -> 60 | N4: =M4*J4 -> 60
A5: Home | B5: Studio / Self-contained - Standard | C5: Standard | D5: Fans | E5: 2 | F5: 60 | G5: 8 | H5: 1 | I5: Yes | J5: 1.2 | K5: =E5*F5*G5*H5 -> 960 | L5: =K5/1000 -> 0.96 | M5: =E5*F5 -> 120 | N5: =M5*J5 -> 144
A6: Home | B6: Studio / Self-contained - Standard | C6: Standard | D6: Television | E6: 1 | F6: 100 | G6: 6 | H6: 1 | I6: Optional | J6: 1.2 | K6: =E6*F6*G6*H6 -> 600 | L6: =K6/1000 -> 0.6 | M6: =E6*F6 -> 100 | N6: =M6*J6 -> 120
A7: Home | B7: Studio / Self-contained - Standard | C7: Standard | D7: Decoder | E7: 1 | F7: 25 | G7: 6 | H7: 1 | I7: Optional | J7: 1 | K7: =E7*F7*G7*H7 -> 150 | L7: =K7/1000 -> 0.15 | M7: =E7*F7 -> 25 | N7: =M7*J7 -> 25
A8: Home | B8: Studio / Self-contained - Standard | C8: Standard | D8: Refrigerator | E8: 1 | F8: 150 | G8: 24 | H8: 0.4 | I8: Yes | J8: 2 | K8: =E8*F8*G8*H8 -> 1440 | L8: =K8/1000 -> 1.44 | M8: =E8*F8 -> 150 | N8: =M8*J8 -> 300
A9: Home | B9: Studio / Self-contained - Standard | C9: Standard | D9: WiFi Router | E9: 1 | F9: 15 | G9: 24 | H9: 1 | I9: Yes | J9: 1 | K9: =E9*F9*G9*H9 -> 360 | L9: =K9/1000 -> 0.36 | M9: =E9*F9 -> 15 | N9: =M9*J9 -> 15
A10: Home | B10: Studio / Self-contained - Standard | C10: Standard | D10: Laptop | E10: 1 | F10: 65 | G10: 5 | H10: 1 | I10: Optional | J10: 1 | K10: =E10*F10*G10*H10 -> 325 | L10: =K10/1000 -> 0.325 | M10: =E10*F10 -> 65 | N10: =M10*J10 -> 65
A11: Home | B11: Studio / Self-contained - Standard | C11: Standard | D11: Phone Chargers | E11: 2 | F11: 10 | G11: 3 | H11: 1 | I11: Yes | J11: 1 | K11: =E11*F11*G11*H11 -> 60 | L11: =K11/1000 -> 0.06 | M11: =E11*F11 -> 20 | N11: =M11*J11 -> 20
A12: Home | B12: Studio / Self-contained - Standard | C12: Standard | D12: Microwave | E12: 1 | F12: 1200 | G12: 0.15 | H12: 1 | I12: No | J12: 1 | K12: =E12*F12*G12*H12 -> 180 | L12: =K12/1000 -> 0.18 | M12: =E12*F12 -> 1200 | N12: =M12*J12 -> 1200
A13: Home | B13: 1-Bedroom Flat - Standard | C13: Standard | D13: LED Bulbs | E13: 8 | F13: 10 | G13: 6 | H13: 1 | I13: Yes | J13: 1 | K13: =E13*F13*G13*H13 -> 480 | L13: =K13/1000 -> 0.48 | M13: =E13*F13 -> 80 | N13: =M13*J13 -> 80
A14: Home | B14: 1-Bedroom Flat - Standard | C14: Standard | D14: Fans | E14: 2 | F14: 60 | G14: 8 | H14: 1 | I14: Yes | J14: 1.2 | K14: =E14*F14*G14*H14 -> 960 | L14: =K14/1000 -> 0.96 | M14: =E14*F14 -> 120 | N14: =M14*J14 -> 144
A15: Home | B15: 1-Bedroom Flat - Standard | C15: Standard | D15: Television | E15: 1 | F15: 100 | G15: 6 | H15: 1 | I15: Optional | J15: 1.2 | K15: =E15*F15*G15*H15 -> 600 | L15: =K15/1000 -> 0.6 | M15: =E15*F15 -> 100 | N15: =M15*J15 -> 120
... A312: School | B312: Boarding School Common Services | C312: Institution | D312: Fans | E312: 20 | F312: 60 | G312: 8 | H312: 1 | I312: Optional | J312: 1.2 | K312: =E312*F312*G312*H312 -> 9600 | L312: =K312/1000 -> 9.6 | M312: =E312*F312 -> 1200 | N312: =M312*J312 -> 1440

Sheet Appliance_Input
A1: Appliance Input
A3: Equipment | B3: Qty | C3: Wattage W | D3: Hours/Day | E3: Duty Cycle | F3: Effective_Watts | G3: Daily_kWh | H3: Monthly_kWh | I3: Peak_Watts | J3: Notes | K3: Appliance Totals
A4: =IF(User_Inputs!$D$11="","", INDEX( CHOOSE(User_Inputs!$D$11, Appliance_Library!D4:D12, Appliance_Library!D13:D22, Appliance_Library!D23:D33, Appliance_Library!D34:D46, Appliance_Library!D47:D60, Appliance_Library!D61:D73, Appliance_Library!D74:D82, Appliance_Library!D83:D92, Appliance_Library!D93:D102, Appliance_Library!D103:D111, Appliance_Library!D112:D120, Appliance_Library!D121:D128, Appliance_Library!D129:D133, Appliance_Library!D134:D140, Appliance_Library!D141:D148, Appliance_Library!D149:D156, Appliance_Library!D157:D163, Appliance_Library!D164:D173, Appliance_Library!D174:D180, Appliance_Library!D181:D186, Appliance_Library!D187:D191, Appliance_Library!D192:D197, Appliance_Library!D198:D202, Appliance_Library!D203:D208, Appliance_Library!D209:D213, Appliance_Library!D214:D219, Appliance_Library!D220:D223, Appliance_Library!D224:D228, Appliance_Library!D229:D233, Appliance_Library!D234:D241, Appliance_Library!D242:D248, Appliance_Library!D249:D256, Appliance_Library!D257:D265, Appliance_Library!D266:D272, Appliance_Library!D273:D279, Appliance_Library!D280:D286, Appliance_Library!D287:D292, Appliance_Library!D293:D298, Appliance_Library!D299:D305, Appliance_Library!D306:D312 ), ROW()-ROW($D$4)+1)) -> LED Bulbs | B4: =IF(User_Inputs!$D$11="","", INDEX( CHOOSE(User_Inputs!$D$11, Appliance_Library!E4:E12, Appliance_Library!E13:E22, Appliance_Library!E23:E33, Appliance_Library!E34:E46, Appliance_Library!E47:E60, Appliance_Library!E61:E73, Appliance_Library!E74:E82, Appliance_Library!E83:E92, Appliance_Library!E93:E102, Appliance_Library!E103:E111, Appliance_Library!E112:E120, Appliance_Library!E121:E128, Appliance_Library!E129:E133, Appliance_Library!E134:E140, Appliance_Library!E141:E148, Appliance_Library!E149:E156, Appliance_Library!E157:E163, Appliance_Library!E164:E173, Appliance_Library!E174:E180, Appliance_Library!E181:E186, Appliance_Library!E187:E191, Appliance_Library!E192:E197, Appliance_Library!E198:E202, Appliance_Library!E203:E208, Appliance_Library!E209:E213, Appliance_Library!E214:E219, Appliance_Library!E220:E223, Appliance_Library!E224:E228, Appliance_Library!E229:E233, Appliance_Library!E234:E241, Appliance_Library!E242:E248, Appliance_Library!E249:E256, Appliance_Library!E257:E265, Appliance_Library!E266:E272, Appliance_Library!E273:E279, Appliance_Library!E280:E286, Appliance_Library!E287:E292, Appliance_Library!E293:E298, Appliance_Library!E299:E305, Appliance_Library!E306:E312 ), ROW()-ROW($E$4)+1)) -> 12 | C4: =IF(User_Inputs!$D$11="","", INDEX( CHOOSE(User_Inputs!$D$11, Appliance_Library!F4:F12, Appliance_Library!F13:F22, Appliance_Library!F23:F33, Appliance_Library!F34:F46, Appliance_Library!F47:F60, Appliance_Library!F61:F73, Appliance_Library!F74:F82, Appliance_Library!F83:F92, Appliance_Library!F93:F102, Appliance_Library!F103:F111, Appliance_Library!F112:F120, Appliance_Library!F121:F128, Appliance_Library!F129:F133, Appliance_Library!F134:F140, Appliance_Library!F141:F148, Appliance_Library!F149:F156, Appliance_Library!F157:F163, Appliance_Library!F164:F173, Appliance_Library!F174:F180, Appliance_Library!F181:F186, Appliance_Library!F187:F191, Appliance_Library!F192:F197, Appliance_Library!F198:F202, Appliance_Library!F203:F208, Appliance_Library!F209:F213, Appliance_Library!F214:F219, Appliance_Library!F220:F223, Appliance_Library!F224:F228, Appliance_Library!F229:F233, Appliance_Library!F234:F241, Appliance_Library!F242:F248, Appliance_Library!F249:F256, Appliance_Library!F257:F265, Appliance_Library!F266:F272, Appliance_Library!F273:F279, Appliance_Library!F280:F286, Appliance_Library!F287:F292, Appliance_Library!F293:F298, Appliance_Library!F299:F305, Appliance_Library!F306:F312 ), ROW()-ROW($F$4)+1)) -> 10 | D4: =IF(User_Inputs!$D$11="","", INDEX( CHOOSE(User_Inputs!$D$11, Appliance_Library!G4:G12, Appliance_Library!G13:G22, Appliance_Library!G23:G33, Appliance_Library!G34:G46, Appliance_Library!G47:G60, Appliance_Library!G61:G73, Appliance_Library!G74:G82, Appliance_Library!G83:G92, Appliance_Library!G93:G102, Appliance_Library!G103:G111, Appliance_Library!G112:G120, Appliance_Library!G121:G128, Appliance_Library!G129:G133, Appliance_Library!G134:G140, Appliance_Library!G141:G148, Appliance_Library!G149:G156, Appliance_Library!G157:G163, Appliance_Library!G164:G173, Appliance_Library!G174:G180, Appliance_Library!G181:G186, Appliance_Library!G187:G191, Appliance_Library!G192:G197, Appliance_Library!G198:G202, Appliance_Library!G203:G208, Appliance_Library!G209:G213, Appliance_Library!G214:G219, Appliance_Library!G220:G223, Appliance_Library!G224:G228, Appliance_Library!G229:G233, Appliance_Library!G234:G241, Appliance_Library!G242:G248, Appliance_Library!G249:G256, Appliance_Library!G257:G265, Appliance_Library!G266:G272, Appliance_Library!G273:G279, Appliance_Library!G280:G286, Appliance_Library!G287:G292, Appliance_Library!G293:G298, Appliance_Library!G299:G305, Appliance_Library!G306:G312 ), ROW()-ROW($G$4)+1)) -> 6 | E4: =IF(User_Inputs!$D$11="","", INDEX( CHOOSE(User_Inputs!$D$11, Appliance_Library!H4:H12, Appliance_Library!H13:H22, Appliance_Library!H23:H33, Appliance_Library!H34:H46, Appliance_Library!H47:H60, Appliance_Library!H61:H73, Appliance_Library!H74:H82, Appliance_Library!H83:H92, Appliance_Library!H93:H102, Appliance_Library!H103:H111, Appliance_Library!H112:H120, Appliance_Library!H121:H128, Appliance_Library!H129:H133, Appliance_Library!H134:H140, Appliance_Library!H141:H148, Appliance_Library!H149:H156, Appliance_Library!H157:H163, Appliance_Library!H164:H173, Appliance_Library!H174:H180, Appliance_Library!H181:H186, Appliance_Library!H187:H191, Appliance_Library!H192:H197, Appliance_Library!H198:H202, Appliance_Library!H203:H208, Appliance_Library!H209:H213, Appliance_Library!H214:H219, Appliance_Library!H220:H223, Appliance_Library!H224:H228, Appliance_Library!H229:H233, Appliance_Library!H234:H241, Appliance_Library!H242:H248, Appliance_Library!H249:H256, Appliance_Library!H257:H265, Appliance_Library!H266:H272, Appliance_Library!H273:H279, Appliance_Library!H280:H286, Appliance_Library!H287:H292, Appliance_Library!H293:H298, Appliance_Library!H299:H305, Appliance_Library!H306:H312 ), ROW()-ROW($H$4)+1)) -> 1 | F4: =IFERROR(C4*E4,0) -> 10 | G4: =IFERROR(F4*B4*D4/1000,0) -> 0.72 | H4: =G4*30 -> 21.6 | I4: =IFERROR(F4*B4,0) -> 120 | K4: Daily kWh | L4: =SUM(G4:G23) -> 8.055
A5: =IF(User_Inputs!$D$11="","", INDEX( CHOOSE(User_Inputs!$D$11, Appliance_Library!D5:D13, Appliance_Library!D14:D23, Appliance_Library!D24:D34, Appliance_Library!D35:D47, Appliance_Library!D48:D61, Appliance_Library!D62:D74, Appliance_Library!D75:D83, Appliance_Library!D84:D93, Appliance_Library!D94:D103, Appliance_Library!D104:D112, Appliance_Library!D113:D121, Appliance_Library!D122:D129, Appliance_Library!D130:D134, Appliance_Library!D135:D141, Appliance_Library!D142:D149, Appliance_Library!D150:D157, Appliance_Library!D158:D164, Appliance_Library!D165:D174, Appliance_Library!D175:D181, Appliance_Library!D182:D187, Appliance_Library!D188:D192, Appliance_Library!D193:D198, Appliance_Library!D199:D203, Appliance_Library!D204:D209, Appliance_Library!D210:D214, Appliance_Library!D215:D220, Appliance_Library!D221:D224, Appliance_Library!D225:D229, Appliance_Library!D230:D234, Appliance_Library!D235:D242, Appliance_Library!D243:D249, Appliance_Library!D250:D257, Appliance_Library!D258:D266, Appliance_Library!D267:D273, Appliance_Library!D274:D280, Appliance_Library!D281:D287, Appliance_Library!D288:D293, Appliance_Library!D294:D299, Appliance_Library!D300:D306, Appliance_Library!D307:D313 ), ROW()-ROW($D$4)+1)) -> Television | B5: =IF(User_Inputs!$D$11="","", INDEX( CHOOSE(User_Inputs!$D$11, Appliance_Library!E5:E13, Appliance_Library!E14:E23, Appliance_Library!E24:E34, Appliance_Library!E35:E47, Appliance_Library!E48:E61, Appliance_Library!E62:E74, Appliance_Library!E75:E83, Appliance_Library!E84:E93, Appliance_Library!E94:E103, Appliance_Library!E104:E112, Appliance_Library!E113:E121, Appliance_Library!E122:E129, Appliance_Library!E130:E134, Appliance_Library!E135:E141, Appliance_Library!E142:E149, Appliance_Library!E150:E157, Appliance_Library!E158:E164, Appliance_Library!E165:E174, Appliance_Library!E175:E181, Appliance_Library!E182:E187, Appliance_Library!E188:E192, Appliance_Library!E193:E198, Appliance_Library!E199:E203, Appliance_Library!E204:E209, Appliance_Library!E210:E214, Appliance_Library!E215:E220, Appliance_Library!E221:E224, Appliance_Library!E225:E229, Appliance_Library!E230:E234, Appliance_Library!E235:E242, Appliance_Library!E243:E249, Appliance_Library!E250:E257, Appliance_Library!E258:E266, Appliance_Library!E267:E273, Appliance_Library!E274:E280, Appliance_Library!E281:E287, Appliance_Library!E288:E293, Appliance_Library!E294:E299, Appliance_Library!E300:E306, Appliance_Library!E307:E313 ), ROW()-ROW($E$4)+1)) -> 1 | C5: =IF(User_Inputs!$D$11="","", INDEX( CHOOSE(User_Inputs!$D$11, Appliance_Library!F5:F13, Appliance_Library!F14:F23, Appliance_Library!F24:F34, Appliance_Library!F35:F47, Appliance_Library!F48:F61, Appliance_Library!F62:F74, Appliance_Library!F75:F83, Appliance_Library!F84:F93, Appliance_Library!F94:F103, Appliance_Library!F104:F112, Appliance_Library!F113:F121, Appliance_Library!F122:F129, Appliance_Library!F130:F134, Appliance_Library!F135:F141, Appliance_Library!F142:F149, Appliance_Library!F150:F157, Appliance_Library!F158:F164, Appliance_Library!F165:F174, Appliance_Library!F175:F181, Appliance_Library!F182:F187, Appliance_Library!F188:F192, Appliance_Library!F193:F198, Appliance_Library!F199:F203, Appliance_Library!F204:F209, Appliance_Library!F210:F214, Appliance_Library!F215:F220, Appliance_Library!F221:F224, Appliance_Library!F225:F229, Appliance_Library!F230:F234, Appliance_Library!F235:F242, Appliance_Library!F243:F249, Appliance_Library!F250:F257, Appliance_Library!F258:F266, Appliance_Library!F267:F273, Appliance_Library!F274:F280, Appliance_Library!F281:F287, Appliance_Library!F288:F293, Appliance_Library!F294:F299, Appliance_Library!F300:F306, Appliance_Library!F307:F313 ), ROW()-ROW($F$4)+1)) -> 100 | D5: =IF(User_Inputs!$D$11="","", INDEX( CHOOSE(User_Inputs!$D$11, Appliance_Library!G5:G13, Appliance_Library!G14:G23, Appliance_Library!G24:G34, Appliance_Library!G35:G47, Appliance_Library!G48:G61, Appliance_Library!G62:G74, Appliance_Library!G75:G83, Appliance_Library!G84:G93, Appliance_Library!G94:G103, Appliance_Library!G104:G112, Appliance_Library!G113:G121, Appliance_Library!G122:G129, Appliance_Library!G130:G134, Appliance_Library!G135:G141, Appliance_Library!G142:G149, Appliance_Library!G150:G157, Appliance_Library!G158:G164, Appliance_Library!G165:G174, Appliance_Library!G175:G181, Appliance_Library!G182:G187, Appliance_Library!G188:G192, Appliance_Library!G193:G198, Appliance_Library!G199:G203, Appliance_Library!G204:G209, Appliance_Library!G210:G214, Appliance_Library!G215:G220, Appliance_Library!G221:G224, Appliance_Library!G225:G229, Appliance_Library!G230:G234, Appliance_Library!G235:G242, Appliance_Library!G243:G249, Appliance_Library!G250:G257, Appliance_Library!G258:G266, Appliance_Library!G267:G273, Appliance_Library!G274:G280, Appliance_Library!G281:G287, Appliance_Library!G288:G293, Appliance_Library!G294:G299, Appliance_Library!G300:G306, Appliance_Library!G307:G313 ), ROW()-ROW($G$4)+1)) -> 6 | E5: =IF(User_Inputs!$D$11="","", INDEX( CHOOSE(User_Inputs!$D$11, Appliance_Library!H5:H13, Appliance_Library!H14:H23, Appliance_Library!H24:H34, Appliance_Library!H35:H47, Appliance_Library!H48:H61, Appliance_Library!H62:H74, Appliance_Library!H75:H83, Appliance_Library!H84:H93, Appliance_Library!H94:H103, Appliance_Library!H104:H112, Appliance_Library!H113:H121, Appliance_Library!H122:H129, Appliance_Library!H130:H134, Appliance_Library!H135:H141, Appliance_Library!H142:H149, Appliance_Library!H150:H157, Appliance_Library!H158:H164, Appliance_Library!H165:H174, Appliance_Library!H175:H181, Appliance_Library!H182:H187, Appliance_Library!H188:H192, Appliance_Library!H193:H198, Appliance_Library!H199:H203, Appliance_Library!H204:H209, Appliance_Library!H210:H214, Appliance_Library!H215:H220, Appliance_Library!H221:H224, Appliance_Library!H225:H229, Appliance_Library!H230:H234, Appliance_Library!H235:H242, Appliance_Library!H243:H249, Appliance_Library!H250:H257, Appliance_Library!H258:H266, Appliance_Library!H267:H273, Appliance_Library!H274:H280, Appliance_Library!H281:H287, Appliance_Library!H288:H293, Appliance_Library!H294:H299, Appliance_Library!H300:H306, Appliance_Library!H307:H313 ), ROW()-ROW($H$4)+1)) -> 1 | F5: =IFERROR(C5*E5,0) -> 100 | G5: =IFERROR(F5*B5*D5/1000,0) -> 0.6 | H5: =G5*30 -> 18 | I5: =IFERROR(F5*B5,0) -> 100 | K5: Monthly kWh | L5: =SUM(H4:H23) -> 241.65
A6: =IF(User_Inputs!$D$11="","", INDEX( CHOOSE(User_Inputs!$D$11, Appliance_Library!D6:D14, Appliance_Library!D15:D24, Appliance_Library!D25:D35, Appliance_Library!D36:D48, Appliance_Library!D49:D62, Appliance_Library!D63:D75, Appliance_Library!D76:D84, Appliance_Library!D85:D94, Appliance_Library!D95:D104, Appliance_Library!D105:D113, Appliance_Library!D114:D122, Appliance_Library!D123:D130, Appliance_Library!D131:D135, Appliance_Library!D136:D142, Appliance_Library!D143:D150, Appliance_Library!D151:D158, Appliance_Library!D159:D165, Appliance_Library!D166:D175, Appliance_Library!D176:D182, Appliance_Library!D183:D188, Appliance_Library!D189:D193, Appliance_Library!D194:D199, Appliance_Library!D200:D204, Appliance_Library!D205:D210, Appliance_Library!D211:D215, Appliance_Library!D216:D221, Appliance_Library!D222:D225, Appliance_Library!D226:D230, Appliance_Library!D231:D235, Appliance_Library!D236:D243, Appliance_Library!D244:D250, Appliance_Library!D251:D258, Appliance_Library!D259:D267, Appliance_Library!D268:D274, Appliance_Library!D275:D281, Appliance_Library!D282:D288, Appliance_Library!D289:D294, Appliance_Library!D295:D300, Appliance_Library!D301:D307, Appliance_Library!D308:D314 ), ROW()-ROW($D$4)+1)) -> Refrigerator | B6: =IF(User_Inputs!$D$11="","", INDEX( CHOOSE(User_Inputs!$D$11, Appliance_Library!E6:E14, Appliance_Library!E15:E24, Appliance_Library!E25:E35, Appliance_Library!E36:E48, Appliance_Library!E49:E62, Appliance_Library!E63:E75, Appliance_Library!E76:E84, Appliance_Library!E85:E94, Appliance_Library!E95:E104, Appliance_Library!E105:E113, Appliance_Library!E114:E122, Appliance_Library!E123:E130, Appliance_Library!E131:E135, Appliance_Library!E136:E142, Appliance_Library!E143:E150, Appliance_Library!E151:E158, Appliance_Library!E159:E165, Appliance_Library!E166:E175, Appliance_Library!E176:E182, Appliance_Library!E183:E188, Appliance_Library!E189:E193, Appliance_Library!E194:E199, Appliance_Library!E200:E204, Appliance_Library!E205:E210, Appliance_Library!E211:E215, Appliance_Library!E216:E221, Appliance_Library!E222:E225, Appliance_Library!E226:E230, Appliance_Library!E231:E235, Appliance_Library!E236:E243, Appliance_Library!E244:E250, Appliance_Library!E251:E258, Appliance_Library!E259:E267, Appliance_Library!E268:E274, Appliance_Library!E275:E281, Appliance_Library!E282:E288, Appliance_Library!E289:E294, Appliance_Library!E295:E300, Appliance_Library!E301:E307, Appliance_Library!E308:E314 ), ROW()-ROW($E$4)+1)) -> 1 | C6: =IF(User_Inputs!$D$11="","", INDEX( CHOOSE(User_Inputs!$D$11, Appliance_Library!F6:F14, Appliance_Library!F15:F24, Appliance_Library!F25:F35, Appliance_Library!F36:F48, Appliance_Library!F49:F62, Appliance_Library!F63:F75, Appliance_Library!F76:F84, Appliance_Library!F85:F94, Appliance_Library!F95:F104, Appliance_Library!F105:F113, Appliance_Library!F114:F122, Appliance_Library!F123:F130, Appliance_Library!F131:F135, Appliance_Library!F136:F142, Appliance_Library!F143:F150, Appliance_Library!F151:F158, Appliance_Library!F159:F165, Appliance_Library!F166:F175, Appliance_Library!F176:F182, Appliance_Library!F183:F188, Appliance_Library!F189:F193, Appliance_Library!F194:F199, Appliance_Library!F200:F204, Appliance_Library!F205:F210, Appliance_Library!F211:F215, Appliance_Library!F216:F221, Appliance_Library!F222:F225, Appliance_Library!F226:F230, Appliance_Library!F231:F235, Appliance_Library!F236:F243, Appliance_Library!F244:F250, Appliance_Library!F251:F258, Appliance_Library!F259:F267, Appliance_Library!F268:F274, Appliance_Library!F275:F281, Appliance_Library!F282:F288, Appliance_Library!F289:F294, Appliance_Library!F295:F300, Appliance_Library!F301:F307, Appliance_Library!F308:F314 ), ROW()-ROW($F$4)+1)) -> 150 | D6: =IF(User_Inputs!$D$11="","", INDEX( CHOOSE(User_Inputs!$D$11, Appliance_Library!G6:G14, Appliance_Library!G15:G24, Appliance_Library!G25:G35, Appliance_Library!G36:G48, Appliance_Library!G49:G62, Appliance_Library!G63:G75, Appliance_Library!G76:G84, Appliance_Library!G85:G94, Appliance_Library!G95:G104, Appliance_Library!G105:G113, Appliance_Library!G114:G122, Appliance_Library!G123:G130, Appliance_Library!G131:G135, Appliance_Library!G136:G142, Appliance_Library!G143:G150, Appliance_Library!G151:G158, Appliance_Library!G159:G165, Appliance_Library!G166:G175, Appliance_Library!G176:G182, Appliance_Library!G183:G188, Appliance_Library!G189:G193, Appliance_Library!G194:G199, Appliance_Library!G200:G204, Appliance_Library!G205:G210, Appliance_Library!G211:G215, Appliance_Library!G216:G221, Appliance_Library!G222:G225, Appliance_Library!G226:G230, Appliance_Library!G231:G235, Appliance_Library!G236:G243, Appliance_Library!G244:G250, Appliance_Library!G251:G258, Appliance_Library!G259:G267, Appliance_Library!G268:G274, Appliance_Library!G275:G281, Appliance_Library!G282:G288, Appliance_Library!G289:G294, Appliance_Library!G295:G300, Appliance_Library!G301:G307, Appliance_Library!G308:G314 ), ROW()-ROW($G$4)+1)) -> 24 | E6: =IF(User_Inputs!$D$11="","", INDEX( CHOOSE(User_Inputs!$D$11, Appliance_Library!H6:H14, Appliance_Library!H15:H24, Appliance_Library!H25:H35, Appliance_Library!H36:H48, Appliance_Library!H49:H62, Appliance_Library!H63:H75, Appliance_Library!H76:H84, Appliance_Library!H85:H94, Appliance_Library!H95:H104, Appliance_Library!H105:H113, Appliance_Library!H114:H122, Appliance_Library!H123:H130, Appliance_Library!H131:H135, Appliance_Library!H136:H142, Appliance_Library!H143:H150, Appliance_Library!H151:H158, Appliance_Library!H159:H165, Appliance_Library!H166:H175, Appliance_Library!H176:H182, Appliance_Library!H183:H188, Appliance_Library!H189:H193, Appliance_Library!H194:H199, Appliance_Library!H200:H204, Appliance_Library!H205:H210, Appliance_Library!H211:H215, Appliance_Library!H216:H221, Appliance_Library!H222:H225, Appliance_Library!H226:H230, Appliance_Library!H231:H235, Appliance_Library!H236:H243, Appliance_Library!H244:H250, Appliance_Library!H251:H258, Appliance_Library!H259:H267, Appliance_Library!H268:H274, Appliance_Library!H275:H281, Appliance_Library!H282:H288, Appliance_Library!H289:H294, Appliance_Library!H295:H300, Appliance_Library!H301:H307, Appliance_Library!H308:H314 ), ROW()-ROW($H$4)+1)) -> 0.4 | F6: =IFERROR(C6*E6,0) -> 60 | G6: =IFERROR(F6*B6*D6/1000,0) -> 1.44 | H6: =G6*30 -> 43.2 | I6: =IFERROR(F6*B6,0) -> 60 | K6: Raw Peak kW | L6: =SUM(I4:I23)/1000 -> 2.885
A7: =IF(User_Inputs!$D$11="","", INDEX( CHOOSE(User_Inputs!$D$11, Appliance_Library!D7:D15, Appliance_Library!D16:D25, Appliance_Library!D26:D36, Appliance_Library!D37:D49, Appliance_Library!D50:D63, Appliance_Library!D64:D76, Appliance_Library!D77:D85, Appliance_Library!D86:D95, Appliance_Library!D96:D105, Appliance_Library!D106:D114, Appliance_Library!D115:D123, Appliance_Library!D124:D131, Appliance_Library!D132:D136, Appliance_Library!D137:D143, Appliance_Library!D144:D151, Appliance_Library!D152:D159, Appliance_Library!D160:D166, Appliance_Library!D167:D176, Appliance_Library!D177:D183, Appliance_Library!D184:D189, Appliance_Library!D190:D194, Appliance_Library!D195:D200, Appliance_Library!D201:D205, Appliance_Library!D206:D211, Appliance_Library!D212:D216, Appliance_Library!D217:D222, Appliance_Library!D223:D226, Appliance_Library!D227:D231, Appliance_Library!D232:D236, Appliance_Library!D237:D244, Appliance_Library!D245:D251, Appliance_Library!D252:D259, Appliance_Library!D260:D268, Appliance_Library!D269:D275, Appliance_Library!D276:D282, Appliance_Library!D283:D289, Appliance_Library!D290:D295, Appliance_Library!D296:D301, Appliance_Library!D302:D308, Appliance_Library!D309:D315 ), ROW()-ROW($D$4)+1)) -> Laptop | B7: =IF(User_Inputs!$D$11="","", INDEX( CHOOSE(User_Inputs!$D$11, Appliance_Library!E7:E15, Appliance_Library!E16:E25, Appliance_Library!E26:E36, Appliance_Library!E37:E49, Appliance_Library!E50:E63, Appliance_Library!E64:E76, Appliance_Library!E77:E85, Appliance_Library!E86:E95, Appliance_Library!E96:E105, Appliance_Library!E106:E114, Appliance_Library!E115:E123, Appliance_Library!E124:E131, Appliance_Library!E132:E136, Appliance_Library!E137:E143, Appliance_Library!E144:E151, Appliance_Library!E152:E159, Appliance_Library!E160:E166, Appliance_Library!E167:E176, Appliance_Library!E177:E183, Appliance_Library!E184:E189, Appliance_Library!E190:E194, Appliance_Library!E195:E200, Appliance_Library!E201:E205, Appliance_Library!E206:E211, Appliance_Library!E212:E216, Appliance_Library!E217:E222, Appliance_Library!E223:E226, Appliance_Library!E227:E231, Appliance_Library!E232:E236, Appliance_Library!E237:E244, Appliance_Library!E245:E251, Appliance_Library!E252:E259, Appliance_Library!E260:E268, Appliance_Library!E269:E275, Appliance_Library!E276:E282, Appliance_Library!E283:E289, Appliance_Library!E290:E295, Appliance_Library!E296:E301, Appliance_Library!E302:E308, Appliance_Library!E309:E315 ), ROW()-ROW($E$4)+1)) -> 2 | C7: =IF(User_Inputs!$D$11="","", INDEX( CHOOSE(User_Inputs!$D$11, Appliance_Library!F7:F15, Appliance_Library!F16:F25, Appliance_Library!F26:F36, Appliance_Library!F37:F49, Appliance_Library!F50:F63, Appliance_Library!F64:F76, Appliance_Library!F77:F85, Appliance_Library!F86:F95, Appliance_Library!F96:F105, Appliance_Library!F106:F114, Appliance_Library!F115:F123, Appliance_Library!F124:F131, Appliance_Library!F132:F136, Appliance_Library!F137:F143, Appliance_Library!F144:F151, Appliance_Library!F152:F159, Appliance_Library!F160:F166, Appliance_Library!F167:F176, Appliance_Library!F177:F183, Appliance_Library!F184:F189, Appliance_Library!F190:F194, Appliance_Library!F195:F200, Appliance_Library!F201:F205, Appliance_Library!F206:F211, Appliance_Library!F212:F216, Appliance_Library!F217:F222, Appliance_Library!F223:F226, Appliance_Library!F227:F231, Appliance_Library!F232:F236, Appliance_Library!F237:F244, Appliance_Library!F245:F251, Appliance_Library!F252:F259, Appliance_Library!F260:F268, Appliance_Library!F269:F275, Appliance_Library!F276:F282, Appliance_Library!F283:F289, Appliance_Library!F290:F295, Appliance_Library!F296:F301, Appliance_Library!F302:F308, Appliance_Library!F309:F315 ), ROW()-ROW($F$4)+1)) -> 65 | D7: =IF(User_Inputs!$D$11="","", INDEX( CHOOSE(User_Inputs!$D$11, Appliance_Library!G7:G15, Appliance_Library!G16:G25, Appliance_Library!G26:G36, Appliance_Library!G37:G49, Appliance_Library!G50:G63, Appliance_Library!G64:G76, Appliance_Library!G77:G85, Appliance_Library!G86:G95, Appliance_Library!G96:G105, Appliance_Library!G106:G114, Appliance_Library!G115:G123, Appliance_Library!G124:G131, Appliance_Library!G132:G136, Appliance_Library!G137:G143, Appliance_Library!G144:G151, Appliance_Library!G152:G159, Appliance_Library!G160:G166, Appliance_Library!G167:G176, Appliance_Library!G177:G183, Appliance_Library!G184:G189, Appliance_Library!G190:G194, Appliance_Library!G195:G200, Appliance_Library!G201:G205, Appliance_Library!G206:G211, Appliance_Library!G212:G216, Appliance_Library!G217:G222, Appliance_Library!G223:G226, Appliance_Library!G227:G231, Appliance_Library!G232:G236, Appliance_Library!G237:G244, Appliance_Library!G245:G251, Appliance_Library!G252:G259, Appliance_Library!G260:G268, Appliance_Library!G269:G275, Appliance_Library!G276:G282, Appliance_Library!G283:G289, Appliance_Library!G290:G295, Appliance_Library!G296:G301, Appliance_Library!G302:G308, Appliance_Library!G309:G315 ), ROW()-ROW($G$4)+1)) -> 5 | E7: =IF(User_Inputs!$D$11="","", INDEX( CHOOSE(User_Inputs!$D$11, Appliance_Library!H7:H15, Appliance_Library!H16:H25, Appliance_Library!H26:H36, Appliance_Library!H37:H49, Appliance_Library!H50:H63, Appliance_Library!H64:H76, Appliance_Library!H77:H85, Appliance_Library!H86:H95, Appliance_Library!H96:H105, Appliance_Library!H106:H114, Appliance_Library!H115:H123, Appliance_Library!H124:H131, Appliance_Library!H132:H136, Appliance_Library!H137:H143, Appliance_Library!H144:H151, Appliance_Library!H152:H159, Appliance_Library!H160:H166, Appliance_Library!H167:H176, Appliance_Library!H177:H183, Appliance_Library!H184:H189, Appliance_Library!H190:H194, Appliance_Library!H195:H200, Appliance_Library!H201:H205, Appliance_Library!H206:H211, Appliance_Library!H212:H216, Appliance_Library!H217:H222, Appliance_Library!H223:H226, Appliance_Library!H227:H231, Appliance_Library!H232:H236, Appliance_Library!H237:H244, Appliance_Library!H245:H251, Appliance_Library!H252:H259, Appliance_Library!H260:H268, Appliance_Library!H269:H275, Appliance_Library!H276:H282, Appliance_Library!H283:H289, Appliance_Library!H290:H295, Appliance_Library!H296:H301, Appliance_Library!H302:H308, Appliance_Library!H309:H315 ), ROW()-ROW($H$4)+1)) -> 1 | F7: =IFERROR(C7*E7,0) -> 65 | G7: =IFERROR(F7*B7*D7/1000,0) -> 0.65 | H7: =G7*30 -> 19.5 | I7: =IFERROR(F7*B7,0) -> 130 | K7: Diversity-adjusted Peak kW | L7: =L6*0.65 -> 1.87525
A8: =IF(User_Inputs!$D$11="","", INDEX( CHOOSE(User_Inputs!$D$11, Appliance_Library!D8:D16, Appliance_Library!D17:D26, Appliance_Library!D27:D37, Appliance_Library!D38:D50, Appliance_Library!D51:D64, Appliance_Library!D65:D77, Appliance_Library!D78:D86, Appliance_Library!D87:D96, Appliance_Library!D97:D106, Appliance_Library!D107:D115, Appliance_Library!D116:D124, Appliance_Library!D125:D132, Appliance_Library!D133:D137, Appliance_Library!D138:D144, Appliance_Library!D145:D152, Appliance_Library!D153:D160, Appliance_Library!D161:D167, Appliance_Library!D168:D177, Appliance_Library!D178:D184, Appliance_Library!D185:D190, Appliance_Library!D191:D195, Appliance_Library!D196:D201, Appliance_Library!D202:D206, Appliance_Library!D207:D212, Appliance_Library!D213:D217, Appliance_Library!D218:D223, Appliance_Library!D224:D227, Appliance_Library!D228:D232, Appliance_Library!D233:D237, Appliance_Library!D238:D245, Appliance_Library!D246:D252, Appliance_Library!D253:D260, Appliance_Library!D261:D269, Appliance_Library!D270:D276, Appliance_Library!D277:D283, Appliance_Library!D284:D290, Appliance_Library!D291:D296, Appliance_Library!D297:D302, Appliance_Library!D303:D309, Appliance_Library!D310:D316 ), ROW()-ROW($D$4)+1)) -> Sound Bar | B8: =IF(User_Inputs!$D$11="","", INDEX( CHOOSE(User_Inputs!$D$11, Appliance_Library!E8:E16, Appliance_Library!E17:E26, Appliance_Library!E27:E37, Appliance_Library!E38:E50, Appliance_Library!E51:E64, Appliance_Library!E65:E77, Appliance_Library!E78:E86, Appliance_Library!E87:E96, Appliance_Library!E97:E106, Appliance_Library!E107:E115, Appliance_Library!E116:E124, Appliance_Library!E125:E132, Appliance_Library!E133:E137, Appliance_Library!E138:E144, Appliance_Library!E145:E152, Appliance_Library!E153:E160, Appliance_Library!E161:E167, Appliance_Library!E168:E177, Appliance_Library!E178:E184, Appliance_Library!E185:E190, Appliance_Library!E191:E195, Appliance_Library!E196:E201, Appliance_Library!E202:E206, Appliance_Library!E207:E212, Appliance_Library!E213:E217, Appliance_Library!E218:E223, Appliance_Library!E224:E227, Appliance_Library!E228:E232, Appliance_Library!E233:E237, Appliance_Library!E238:E245, Appliance_Library!E246:E252, Appliance_Library!E253:E260, Appliance_Library!E261:E269, Appliance_Library!E270:E276, Appliance_Library!E277:E283, Appliance_Library!E284:E290, Appliance_Library!E291:E296, Appliance_Library!E297:E302, Appliance_Library!E303:E309, Appliance_Library!E310:E316 ), ROW()-ROW($E$4)+1)) -> 1 | C8: =IF(User_Inputs!$D$11="","", INDEX( CHOOSE(User_Inputs!$D$11, Appliance_Library!F8:F16, Appliance_Library!F17:F26, Appliance_Library!F27:F37, Appliance_Library!F38:F50, Appliance_Library!F51:F64, Appliance_Library!F65:F77, Appliance_Library!F78:F86, Appliance_Library!F87:F96, Appliance_Library!F97:F106, Appliance_Library!F107:F115, Appliance_Library!F116:F124, Appliance_Library!F125:F132, Appliance_Library!F133:F137, Appliance_Library!F138:F144, Appliance_Library!F145:F152, Appliance_Library!F153:F160, Appliance_Library!F161:F167, Appliance_Library!F168:F177, Appliance_Library!F178:F184, Appliance_Library!F185:F190, Appliance_Library!F191:F195, Appliance_Library!F196:F201, Appliance_Library!F202:F206, Appliance_Library!F207:F212, Appliance_Library!F213:F217, Appliance_Library!F218:F223, Appliance_Library!F224:F227, Appliance_Library!F228:F232, Appliance_Library!F233:F237, Appliance_Library!F238:F245, Appliance_Library!F246:F252, Appliance_Library!F253:F260, Appliance_Library!F261:F269, Appliance_Library!F270:F276, Appliance_Library!F277:F283, Appliance_Library!F284:F290, Appliance_Library!F291:F296, Appliance_Library!F297:F302, Appliance_Library!F303:F309, Appliance_Library!F310:F316 ), ROW()-ROW($F$4)+1)) -> 50 | D8: =IF(User_Inputs!$D$11="","", INDEX( CHOOSE(User_Inputs!$D$11, Appliance_Library!G8:G16, Appliance_Library!G17:G26, Appliance_Library!G27:G37, Appliance_Library!G38:G50, Appliance_Library!G51:G64, Appliance_Library!G65:G77, Appliance_Library!G78:G86, Appliance_Library!G87:G96, Appliance_Library!G97:G106, Appliance_Library!G107:G115, Appliance_Library!G116:G124, Appliance_Library!G125:G132, Appliance_Library!G133:G137, Appliance_Library!G138:G144, Appliance_Library!G145:G152, Appliance_Library!G153:G160, Appliance_Library!G161:G167, Appliance_Library!G168:G177, Appliance_Library!G178:G184, Appliance_Library!G185:G190, Appliance_Library!G191:G195, Appliance_Library!G196:G201, Appliance_Library!G202:G206, Appliance_Library!G207:G212, Appliance_Library!G213:G217, Appliance_Library!G218:G223, Appliance_Library!G224:G227, Appliance_Library!G228:G232, Appliance_Library!G233:G237, Appliance_Library!G238:G245, Appliance_Library!G246:G252, Appliance_Library!G253:G260, Appliance_Library!G261:G269, Appliance_Library!G270:G276, Appliance_Library!G277:G283, Appliance_Library!G284:G290, Appliance_Library!G291:G296, Appliance_Library!G297:G302, Appliance_Library!G303:G309, Appliance_Library!G310:G316 ), ROW()-ROW($G$4)+1)) -> 2 | E8: =IF(User_Inputs!$D$11="","", INDEX( CHOOSE(User_Inputs!$D$11, Appliance_Library!H8:H16, Appliance_Library!H17:H26, Appliance_Library!H27:H37, Appliance_Library!H38:H50, Appliance_Library!H51:H64, Appliance_Library!H65:H77, Appliance_Library!H78:H86, Appliance_Library!H87:H96, Appliance_Library!H97:H106, Appliance_Library!H107:H115, Appliance_Library!H116:H124, Appliance_Library!H125:H132, Appliance_Library!H133:H137, Appliance_Library!H138:H144, Appliance_Library!H145:H152, Appliance_Library!H153:H160, Appliance_Library!H161:H167, Appliance_Library!H168:H177, Appliance_Library!H178:H184, Appliance_Library!H185:H190, Appliance_Library!H191:H195, Appliance_Library!H196:H201, Appliance_Library!H202:H206, Appliance_Library!H207:H212, Appliance_Library!H213:H217, Appliance_Library!H218:H223, Appliance_Library!H224:H227, Appliance_Library!H228:H232, Appliance_Library!H233:H237, Appliance_Library!H238:H245, Appliance_Library!H246:H252, Appliance_Library!H253:H260, Appliance_Library!H261:H269, Appliance_Library!H270:H276, Appliance_Library!H277:H283, Appliance_Library!H284:H290, Appliance_Library!H291:H296, Appliance_Library!H297:H302, Appliance_Library!H303:H309, Appliance_Library!H310:H316 ), ROW()-ROW($H$4)+1)) -> 1 | F8: =IFERROR(C8*E8,0) -> 50 | G8: =IFERROR(F8*B8*D8/1000,0) -> 0.1 | H8: =G8*30 -> 3 | I8: =IFERROR(F8*B8,0) -> 50
A9: =IF(User_Inputs!$D$11="","", INDEX( CHOOSE(User_Inputs!$D$11, Appliance_Library!D9:D17, Appliance_Library!D18:D27, Appliance_Library!D28:D38, Appliance_Library!D39:D51, Appliance_Library!D52:D65, Appliance_Library!D66:D78, Appliance_Library!D79:D87, Appliance_Library!D88:D97, Appliance_Library!D98:D107, Appliance_Library!D108:D116, Appliance_Library!D117:D125, Appliance_Library!D126:D133, Appliance_Library!D134:D138, Appliance_Library!D139:D145, Appliance_Library!D146:D153, Appliance_Library!D154:D161, Appliance_Library!D162:D168, Appliance_Library!D169:D178, Appliance_Library!D179:D185, Appliance_Library!D186:D191, Appliance_Library!D192:D196, Appliance_Library!D197:D202, Appliance_Library!D203:D207, Appliance_Library!D208:D213, Appliance_Library!D214:D218, Appliance_Library!D219:D224, Appliance_Library!D225:D228, Appliance_Library!D229:D233, Appliance_Library!D234:D238, Appliance_Library!D239:D246, Appliance_Library!D247:D253, Appliance_Library!D254:D261, Appliance_Library!D262:D270, Appliance_Library!D271:D277, Appliance_Library!D278:D284, Appliance_Library!D285:D291, Appliance_Library!D292:D297, Appliance_Library!D298:D303, Appliance_Library!D304:D310, Appliance_Library!D311:D317 ), ROW()-ROW($D$4)+1)) -> Water Pump | B9: =IF(User_Inputs!$D$11="","", INDEX( CHOOSE(User_Inputs!$D$11, Appliance_Library!E9:E17, Appliance_Library!E18:E27, Appliance_Library!E28:E38, Appliance_Library!E39:E51, Appliance_Library!E52:E65, Appliance_Library!E66:E78, Appliance_Library!E79:E87, Appliance_Library!E88:E97, Appliance_Library!E98:E107, Appliance_Library!E108:E116, Appliance_Library!E117:E125, Appliance_Library!E126:E133, Appliance_Library!E134:E138, Appliance_Library!E139:E145, Appliance_Library!E146:E153, Appliance_Library!E154:E161, Appliance_Library!E162:E168, Appliance_Library!E169:E178, Appliance_Library!E179:E185, Appliance_Library!E186:E191, Appliance_Library!E192:E196, Appliance_Library!E197:E202, Appliance_Library!E203:E207, Appliance_Library!E208:E213, Appliance_Library!E214:E218, Appliance_Library!E219:E224, Appliance_Library!E225:E228, Appliance_Library!E229:E233, Appliance_Library!E234:E238, Appliance_Library!E239:E246, Appliance_Library!E247:E253, Appliance_Library!E254:E261, Appliance_Library!E262:E270, Appliance_Library!E271:E277, Appliance_Library!E278:E284, Appliance_Library!E285:E291, Appliance_Library!E292:E297, Appliance_Library!E298:E303, Appliance_Library!E304:E310, Appliance_Library!E311:E317 ), ROW()-ROW($E$4)+1)) -> 1 | C9: =IF(User_Inputs!$D$11="","", INDEX( CHOOSE(User_Inputs!$D$11, Appliance_Library!F9:F17, Appliance_Library!F18:F27, Appliance_Library!F28:F38, Appliance_Library!F39:F51, Appliance_Library!F52:F65, Appliance_Library!F66:F78, Appliance_Library!F79:F87, Appliance_Library!F88:F97, Appliance_Library!F98:F107, Appliance_Library!F108:F116, Appliance_Library!F117:F125, Appliance_Library!F126:F133, Appliance_Library!F134:F138, Appliance_Library!F139:F145, Appliance_Library!F146:F153, Appliance_Library!F154:F161, Appliance_Library!F162:F168, Appliance_Library!F169:F178, Appliance_Library!F179:F185, Appliance_Library!F186:F191, Appliance_Library!F192:F196, Appliance_Library!F197:F202, Appliance_Library!F203:F207, Appliance_Library!F208:F213, Appliance_Library!F214:F218, Appliance_Library!F219:F224, Appliance_Library!F225:F228, Appliance_Library!F229:F233, Appliance_Library!F234:F238, Appliance_Library!F239:F246, Appliance_Library!F247:F253, Appliance_Library!F254:F261, Appliance_Library!F262:F270, Appliance_Library!F271:F277, Appliance_Library!F278:F284, Appliance_Library!F285:F291, Appliance_Library!F292:F297, Appliance_Library!F298:F303, Appliance_Library!F304:F310, Appliance_Library!F311:F317 ), ROW()-ROW($F$4)+1)) -> 750 | D9: =IF(User_Inputs!$D$11="","", INDEX( CHOOSE(User_Inputs!$D$11, Appliance_Library!G9:G17, Appliance_Library!G18:G27, Appliance_Library!G28:G38, Appliance_Library!G39:G51, Appliance_Library!G52:G65, Appliance_Library!G66:G78, Appliance_Library!G79:G87, Appliance_Library!G88:G97, Appliance_Library!G98:G107, Appliance_Library!G108:G116, Appliance_Library!G117:G125, Appliance_Library!G126:G133, Appliance_Library!G134:G138, Appliance_Library!G139:G145, Appliance_Library!G146:G153, Appliance_Library!G154:G161, Appliance_Library!G162:G168, Appliance_Library!G169:G178, Appliance_Library!G179:G185, Appliance_Library!G186:G191, Appliance_Library!G192:G196, Appliance_Library!G197:G202, Appliance_Library!G203:G207, Appliance_Library!G208:G213, Appliance_Library!G214:G218, Appliance_Library!G219:G224, Appliance_Library!G225:G228, Appliance_Library!G229:G233, Appliance_Library!G234:G238, Appliance_Library!G239:G246, Appliance_Library!G247:G253, Appliance_Library!G254:G261, Appliance_Library!G262:G270, Appliance_Library!G271:G277, Appliance_Library!G278:G284, Appliance_Library!G285:G291, Appliance_Library!G292:G297, Appliance_Library!G298:G303, Appliance_Library!G304:G310, Appliance_Library!G311:G317 ), ROW()-ROW($G$4)+1)) -> 0.5 | E9: =IF(User_Inputs!$D$11="","", INDEX( CHOOSE(User_Inputs!$D$11, Appliance_Library!H9:H17, Appliance_Library!H18:H27, Appliance_Library!H28:H38, Appliance_Library!H39:H51, Appliance_Library!H52:H65, Appliance_Library!H66:H78, Appliance_Library!H79:H87, Appliance_Library!H88:H97, Appliance_Library!H98:H107, Appliance_Library!H108:H116, Appliance_Library!H117:H125, Appliance_Library!H126:H133, Appliance_Library!H134:H138, Appliance_Library!H139:H145, Appliance_Library!H146:H153, Appliance_Library!H154:H161, Appliance_Library!H162:H168, Appliance_Library!H169:H178, Appliance_Library!H179:H185, Appliance_Library!H186:H191, Appliance_Library!H192:H196, Appliance_Library!H197:H202, Appliance_Library!H203:H207, Appliance_Library!H208:H213, Appliance_Library!H214:H218, Appliance_Library!H219:H224, Appliance_Library!H225:H228, Appliance_Library!H229:H233, Appliance_Library!H234:H238, Appliance_Library!H239:H246, Appliance_Library!H247:H253, Appliance_Library!H254:H261, Appliance_Library!H262:H270, Appliance_Library!H271:H277, Appliance_Library!H278:H284, Appliance_Library!H285:H291, Appliance_Library!H292:H297, Appliance_Library!H298:H303, Appliance_Library!H304:H310, Appliance_Library!H311:H317 ), ROW()-ROW($H$4)+1)) -> 1 | F9: =IFERROR(C9*E9,0) -> 750 | G9: =IFERROR(F9*B9*D9/1000,0) -> 0.375 | H9: =G9*30 -> 11.25 | I9: =IFERROR(F9*B9,0) -> 750
A10: =IF(User_Inputs!$D$11="","", INDEX( CHOOSE(User_Inputs!$D$11, Appliance_Library!D10:D18, Appliance_Library!D19:D28, Appliance_Library!D29:D39, Appliance_Library!D40:D52, Appliance_Library!D53:D66, Appliance_Library!D67:D79, Appliance_Library!D80:D88, Appliance_Library!D89:D98, Appliance_Library!D99:D108, Appliance_Library!D109:D117, Appliance_Library!D118:D126, Appliance_Library!D127:D134, Appliance_Library!D135:D139, Appliance_Library!D140:D146, Appliance_Library!D147:D154, Appliance_Library!D155:D162, Appliance_Library!D163:D169, Appliance_Library!D170:D179, Appliance_Library!D180:D186, Appliance_Library!D187:D192, Appliance_Library!D193:D197, Appliance_Library!D198:D203, Appliance_Library!D204:D208, Appliance_Library!D209:D214, Appliance_Library!D215:D219, Appliance_Library!D220:D225, Appliance_Library!D226:D229, Appliance_Library!D230:D234, Appliance_Library!D235:D239, Appliance_Library!D240:D247, Appliance_Library!D248:D254, Appliance_Library!D255:D262, Appliance_Library!D263:D271, Appliance_Library!D272:D278, Appliance_Library!D279:D285, Appliance_Library!D286:D292, Appliance_Library!D293:D298, Appliance_Library!D299:D304, Appliance_Library!D305:D311, Appliance_Library!D312:D318 ), ROW()-ROW($D$4)+1)) -> Fans | B10: =IF(User_Inputs!$D$11="","", INDEX( CHOOSE(User_Inputs!$D$11, Appliance_Library!E10:E18, Appliance_Library!E19:E28, Appliance_Library!E29:E39, Appliance_Library!E40:E52, Appliance_Library!E53:E66, Appliance_Library!E67:E79, Appliance_Library!E80:E88, Appliance_Library!E89:E98, Appliance_Library!E99:E108, Appliance_Library!E109:E117, Appliance_Library!E118:E126, Appliance_Library!E127:E134, Appliance_Library!E135:E139, Appliance_Library!E140:E146, Appliance_Library!E147:E154, Appliance_Library!E155:E162, Appliance_Library!E163:E169, Appliance_Library!E170:E179, Appliance_Library!E180:E186, Appliance_Library!E187:E192, Appliance_Library!E193:E197, Appliance_Library!E198:E203, Appliance_Library!E204:E208, Appliance_Library!E209:E214, Appliance_Library!E215:E219, Appliance_Library!E220:E225, Appliance_Library!E226:E229, Appliance_Library!E230:E234, Appliance_Library!E235:E239, Appliance_Library!E240:E247, Appliance_Library!E248:E254, Appliance_Library!E255:E262, Appliance_Library!E263:E271, Appliance_Library!E272:E278, Appliance_Library!E279:E285, Appliance_Library!E286:E292, Appliance_Library!E293:E298, Appliance_Library!E299:E304, Appliance_Library!E305:E311, Appliance_Library!E312:E318 ), ROW()-ROW($E$4)+1)) -> 6 | C10: =IF(User_Inputs!$D$11="","", INDEX( CHOOSE(User_Inputs!$D$11, Appliance_Library!F10:F18, Appliance_Library!F19:F28, Appliance_Library!F29:F39, Appliance_Library!F40:F52, Appliance_Library!F53:F66, Appliance_Library!F67:F79, Appliance_Library!F80:F88, Appliance_Library!F89:F98, Appliance_Library!F99:F108, Appliance_Library!F109:F117, Appliance_Library!F118:F126, Appliance_Library!F127:F134, Appliance_Library!F135:F139, Appliance_Library!F140:F146, Appliance_Library!F147:F154, Appliance_Library!F155:F162, Appliance_Library!F163:F169, Appliance_Library!F170:F179, Appliance_Library!F180:F186, Appliance_Library!F187:F192, Appliance_Library!F193:F197, Appliance_Library!F198:F203, Appliance_Library!F204:F208, Appliance_Library!F209:F214, Appliance_Library!F215:F219, Appliance_Library!F220:F225, Appliance_Library!F226:F229, Appliance_Library!F230:F234, Appliance_Library!F235:F239, Appliance_Library!F240:F247, Appliance_Library!F248:F254, Appliance_Library!F255:F262, Appliance_Library!F263:F271, Appliance_Library!F272:F278, Appliance_Library!F279:F285, Appliance_Library!F286:F292, Appliance_Library!F293:F298, Appliance_Library!F299:F304, Appliance_Library!F305:F311, Appliance_Library!F312:F318 ), ROW()-ROW($F$4)+1)) -> 60 | D10: =IF(User_Inputs!$D$11="","", INDEX( CHOOSE(User_Inputs!$D$11, Appliance_Library!G10:G18, Appliance_Library!G19:G28, Appliance_Library!G29:G39, Appliance_Library!G40:G52, Appliance_Library!G53:G66, Appliance_Library!G67:G79, Appliance_Library!G80:G88, Appliance_Library!G89:G98, Appliance_Library!G99:G108, Appliance_Library!G109:G117, Appliance_Library!G118:G126, Appliance_Library!G127:G134, Appliance_Library!G135:G139, Appliance_Library!G140:G146, Appliance_Library!G147:G154, Appliance_Library!G155:G162, Appliance_Library!G163:G169, Appliance_Library!G170:G179, Appliance_Library!G180:G186, Appliance_Library!G187:G192, Appliance_Library!G193:G197, Appliance_Library!G198:G203, Appliance_Library!G204:G208, Appliance_Library!G209:G214, Appliance_Library!G215:G219, Appliance_Library!G220:G225, Appliance_Library!G226:G229, Appliance_Library!G230:G234, Appliance_Library!G235:G239, Appliance_Library!G240:G247, Appliance_Library!G248:G254, Appliance_Library!G255:G262, Appliance_Library!G263:G271, Appliance_Library!G272:G278, Appliance_Library!G279:G285, Appliance_Library!G286:G292, Appliance_Library!G293:G298, Appliance_Library!G299:G304, Appliance_Library!G305:G311, Appliance_Library!G312:G318 ), ROW()-ROW($G$4)+1)) -> 8 | E10: =IF(User_Inputs!$D$11="","", INDEX( CHOOSE(User_Inputs!$D$11, Appliance_Library!H10:H18, Appliance_Library!H19:H28, Appliance_Library!H29:H39, Appliance_Library!H40:H52, Appliance_Library!H53:H66, Appliance_Library!H67:H79, Appliance_Library!H80:H88, Appliance_Library!H89:H98, Appliance_Library!H99:H108, Appliance_Library!H109:H117, Appliance_Library!H118:H126, Appliance_Library!H127:H134, Appliance_Library!H135:H139, Appliance_Library!H140:H146, Appliance_Library!H147:H154, Appliance_Library!H155:H162, Appliance_Library!H163:H169, Appliance_Library!H170:H179, Appliance_Library!H180:H186, Appliance_Library!H187:H192, Appliance_Library!H193:H197, Appliance_Library!H198:H203, Appliance_Library!H204:H208, Appliance_Library!H209:H214, Appliance_Library!H215:H219, Appliance_Library!H220:H225, Appliance_Library!H226:H229, Appliance_Library!H230:H234, Appliance_Library!H235:H239, Appliance_Library!H240:H247, Appliance_Library!H248:H254, Appliance_Library!H255:H262, Appliance_Library!H263:H271, Appliance_Library!H272:H278, Appliance_Library!H279:H285, Appliance_Library!H286:H292, Appliance_Library!H293:H298, Appliance_Library!H299:H304, Appliance_Library!H305:H311, Appliance_Library!H312:H318 ), ROW()-ROW($H$4)+1)) -> 1 | F10: =IFERROR(C10*E10,0) -> 60 | G10: =IFERROR(F10*B10*D10/1000,0) -> 2.88 | H10: =G10*30 -> 86.4 | I10: =IFERROR(F10*B10,0) -> 360
